Workbook

Sheet 1_search_string
A1: population | B1: intervention | C1: outcome | D1: study_methods
A2: *forest* | B2: logging | C2: rut* | D2: remote sensing
A3: AND | B3: cut* | C3: wheel rut* | D3: Earth observation
A4: soil* | B4: clearcut* | C4: wheel-rut* | D4: satellite
A5: AND NOT | B5: clear-cut* | C5: skid trail* | D5: image*
A6: crop* | B6: cutblock* | C6: skidder* | D6: drone
A7: agri* | B7: timber | C7: feller* | D7: uav
B8: salvage | C8: degradation | D8: unmanned aerial vehicle
B9: forestry | C9: disturbance | D9: aerial
B10: wood extraction | C10: compaction | D10: photogrammetr*
B11: harvest | C11: erosion | D11: stereoscop*
B12: select* cut* | C12: vegetation recovery | D12: lidar
B13: select* log* | C13: vegetation disturbance | D13: optical
B14: silvicultur* | C14: slash | D14: radar
B15: high*grading | C15: wood*slash | D15: sensor
B16: block cut* | C16: drainage | D16: *spectral
B17: blowdown | C17: runoff | D17: ndvi
B18: windthrow | C18: windrow* | D18: vegetation index
B19: windsnap | C19: scalping | D19: nbr
... B22: pest* | C22: moisture | D22: digital elevation model
B23: fire*
B24: burn*
A32: ( *forest* AND NOT crop* OR urban OR maize OR wheat OR rice OR corn OR cotton OR grape OR cereal OR agri*) AND (logging OR cut* OR clearcut* OR clear*cut* OR cutblock* OR timber OR salvage OR forestry OR "wood extraction" OR harvest OR "select* cut*" OR "select* log*" OR silvicultur* OR high*grading OR "block cut*" OR blowdown OR windthrow OR windsnap OR insect* OR disease* OR pest* OR fire* OR burn*) AND ( rut* OR "wheel rut*" OR wheel-rut* OR "skid trail*" OR skidder* OR feller* OR soil* OR "soil disturbance" OR compaction OR "soil compaction" OR erosion OR "soil erosion" OR "vegetation recovery" OR "vegetation disturbance" OR slash OR "wood*slash" OR drainage OR runoff OR windrow* OR scalping OR slumping OR "soil nutrient*" OR "soil moisture" ) AND ( "remote sensing" OR "Earth observation" OR "satellite" OR "image*" OR "drone" OR uav OR "unmanned aerial vehicle" OR aerial OR photogrammetr* OR stereoscop* OR lidar OR optical OR radar OR sensor OR *spectral OR ndvi OR "vegetation index" OR nbr OR "normali*ed burn ratio" OR dem OR "digital elevation model" )

Sheet 2_dbase_list
A1: database | B1: roses_diagram_source | C1: date | D1: url | E1: n_results | F1: n_within_dbase_dupes_removed | G1: n_merged_dbase_dupes_removed | H1: search_string
A2: Scopus | B2: database search | C2: 45713 | D2: https://www.scopus.com/search/form.uri#basic | E2: 2588 | F2: 2584 | G2: 2232 | H2: TITLE-ABS-KEY ( ( *forest* AND soil* AND NOT crop* OR agri*) AND ( logging OR cut* OR clearcut* OR clear*cut* OR cutblock* OR timber OR salvage OR forestry OR "wood extraction" OR harvest OR "select* cut*" OR "select* log*" OR silvicultur* OR high*grading OR "block cut*" OR blowdown OR windthrow OR windsnap OR insect* OR disease* OR pest* OR fire* OR burn* ) AND ( rut* OR "wheel rut*" OR wheel-rut* OR "skid trail*" OR skidder* OR feller* OR degradation OR disturbance OR compaction OR erosion OR "vegetation recovery" OR "vegetation disturbance" OR slash OR "wood*slash" OR drainage OR runoff OR windrow* OR scalping OR slumping OR nutrient* OR moisture ) AND ( "remote sensing" OR "Earth observation" OR "satellite" OR "image*" OR "drone" OR uav OR "unmanned aerial vehicle" OR aerial OR photogrammetr* OR stereoscop* OR lidar OR optical OR radar OR sensor OR *spectral OR ndvi OR "vegetation index" OR nbr OR "normali*ed burn ratio" OR dem OR "digital elevation model" ) ) AND ( LIMIT-TO ( LANGUAGE , "English" ) OR LIMIT-TO ( LANGUAGE , "French" ) ) AND ( LIMIT-TO ( DOCTYPE , "ar" ) OR LIMIT-TO ( DOCTYPE , "cp" ) OR LIMIT-TO ( DOCTYPE , "re" ) OR LIMIT-TO ( DOCTYPE , "ch" ) OR LIMIT-TO ( DOCTYPE , "le" ) OR LIMIT-TO ( DOCTYPE , "bk" ) OR LIMIT-TO ( DOCTYPE , "rp" ) )
A3: EBSCOhost | B3: database search | C3: 45714 | D3: https://research.ebsco.com/ | E3: 486 | F3: 485 | G3: 159 | H3: (TI ((*forest* AND soil*) AND (logging OR cut* OR clearcut* OR clear*cut* OR cutblock* OR timber OR salvage OR forestry OR "wood extraction" OR harvest OR "select* cut*" OR "select* log*" OR silvicultur* OR high*grading OR "block cut*" OR blowdown OR windthrow OR windsnap OR insect* OR disease* OR pest* OR fire* OR burn*) AND (rut* OR "wheel rut*" OR wheel-rut* OR "skid trail*" OR skidder* OR feller* OR degradation OR disturbance OR compaction OR erosion OR "vegetation recovery" OR "vegetation disturbance" OR slash OR "wood*slash" OR drainage OR runoff OR windrow* OR scalping OR slumping OR nutrient* OR moisture) AND ("remote sensing" OR "Earth observation" OR "satellite" OR "image*" OR "drone" OR uav OR "unmanned aerial vehicle" OR aerial OR photogrammetr* OR stereoscop* OR lidar OR optical OR radar OR sensor OR *spectral OR ndvi OR "vegetation index" OR nbr OR "normali*ed burn ratio" OR dem OR "digital elevation model"))) OR (AB ((*forest* AND soil*) AND (logging OR cut* OR clearcut* OR clear*cut* OR cutblock* OR timber OR salvage OR forestry OR "wood extraction" OR harvest OR "select* cut*" OR "select* log*" OR silvicultur* OR high*grading OR "block cut*" OR blowdown OR windthrow OR windsnap OR insect* OR disease* OR pest* OR fire* OR burn*) AND (rut* OR "wheel rut*" OR wheel-rut* OR "skid trail*" OR skidder* OR feller* OR degradation OR disturbance OR compaction OR erosion OR "vegetation recovery" OR "vegetation disturbance" OR slash OR "wood*slash" OR drainage OR runoff OR windrow* OR scalping OR slumping OR nutrient* OR moisture) AND ("remote sensing" OR "Earth observation" OR "satellite" OR "image*" OR "drone" OR uav OR "unmanned aerial vehicle" OR aerial OR photogrammetr* OR stereoscop* OR lidar OR optical OR radar OR sensor OR *spectral OR ndvi OR "vegetation index" OR nbr OR "normali*ed burn ratio" OR dem OR "digital elevation model"))) OR (SU ((*forest* AND soil*) AND (logging OR cut* OR clearcut* OR clear*cut* OR cutblock* OR timber OR salvage OR forestry OR "wood extraction" OR harvest OR "select* cut*" OR "select* log*" OR silvicultur* OR high*grading OR "block cut*" OR blowdown OR windthrow OR windsnap OR insect* OR disease* OR pest* OR fire* OR burn*) AND (rut* OR "wheel rut*" OR wheel-rut* OR "skid trail*" OR skidder* OR feller* OR degradation OR disturbance OR compaction OR erosion OR "vegetation recovery" OR "vegetation disturbance" OR slash OR "wood*slash" OR drainage OR runoff OR windrow* OR scalping OR slumping OR nutrient* OR moisture) AND ("remote sensing" OR "Earth observation" OR "satellite" OR "image*" OR "drone" OR uav OR "unmanned aerial vehicle" OR aerial OR photogrammetr* OR stereoscop* OR lidar OR optical OR radar OR sensor OR *spectral OR ndvi OR "vegetation index" OR nbr OR "normali*ed burn ratio" OR dem OR "digital elevation model")))
A4: OpenAlex | B4: database search | C4: 45714 | D4: https://openalex.org/ | E4: 1431 | F4: 1381 | G4: 781 | H4: title & abstract INCLUDE ( *forest* AND soil* AND NOT crop* OR agri* ) AND ( logging OR cut* OR clearcut* OR clear*cut* OR cutblock* OR timber OR salvage OR forestry OR "wood extraction" OR harvest OR "select* cut*" OR "select* log*" OR silvicultur* OR high*grading OR "block cut*" OR blowdown OR windthrow OR windsnap OR insect* OR disease* OR pest* OR fire* OR burn* ) AND ( rut* OR "wheel rut*" OR wheel-rut* OR "skid trail*" OR skidder* OR feller* OR degradation OR disturbance OR compaction OR erosion OR "vegetation recovery" OR "vegetation disturbance" OR slash OR "wood*slash" OR drainage OR runoff OR windrow* OR scalping OR slumping OR nutrient* OR moisture ) AND ( "remote sensing" OR "Earth observation" OR "satellite" OR "image*" OR "drone" OR uav OR "unmanned aerial vehicle" OR aerial OR photogrammetr* OR stereoscop* OR lidar OR optical OR radar OR sensor OR *spectral OR ndvi OR "vegetation index" OR nbr OR "normali*ed burn ratio" OR dem OR "digital elevation model" ), type IS NOT "dataset", type IS NOT "peer-review", type IS NOT "reference-entry", type IS NOT "paratext"
A5: Google Scholar | B5: database search | C5: 45713 | D5: https://scholar.google.ca/ | E5: 300 | F5: 299 | G5: 42 | H5: KEYWORDS (*forest* AND soil*) AND (log* OR *cut* OR harvest* OR timber OR fire OR insect* OR windthrow) AND (degradation OR disturbance OR erosion OR compaction OR *rut*) AND "remote sensing"
A6: OSTR | B6: database search | C6: 45713 | D6: https://ostrnrcan-dostrncan.canada.ca/home | E6: 71 | F6: 67 | G6: 29 | H6: dc.description.abstract: ( *forest* AND soil* ) AND ( logging OR cut* OR clearcut* OR clear*cut* OR cutblock* OR timber OR salvage OR forestry OR "wood extraction" OR harvest OR "select* cut*" OR "select* log*" OR silvicultur* OR high*grading OR "block cut*" OR blowdown OR windthrow OR windsnap OR insect* OR disease* OR pest* OR fire* OR burn* ) AND ( rut* OR "wheel rut*" OR wheel-rut* OR "skid trail*" OR skidder* OR feller* OR degradation OR disturbance OR compaction OR erosion OR "vegetation recovery" OR "vegetation disturbance" OR slash OR "wood*slash" OR drainage OR runoff OR windrow* OR scalping OR slumping OR nutrient* OR moisture ) AND ( "remote sensing" OR "Earth observation" OR "satellite" OR "image*" OR "drone" OR uav OR "unmanned aerial vehicle" OR aerial OR photogrammetr* OR stereoscop* OR lidar OR optical OR radar OR sensor OR *spectral OR ndvi OR "vegetation index" OR nbr OR "normali*ed burn ratio" OR dem OR "digital elevation model" )
A7: MFFP | B7: other search | C7: 45713 | D7: https://mffp.gouv.qc.ca/le-ministere/publications | E7: 0 | H7: remote sensing forest soil degradation
A8: MNRF | B8: other search | E8: 0
A9: USDA Forest Service | B9: other search | C9: 45735 | D9: https://research.fs.usda.gov/treesearch | E9: 15 | F9: 15 | G9: 13 | H9: remote sensing forest soil
D10: RECORDS IDENTIFIED THROUGH DBASE SEARCH | E10: =SUM(E2:E5) -> 4805 | F10: =SUM(F2:F5) -> 4749 | G10: =SUM(G2:G5) -> 3214
D11: RECORDS IDENTIFIED THROUGH OTHER SOURCES | E11: =SUM(E6:E9) -> 86 | F11: =SUM(F6:F9) -> 82 | G11: =SUM(G6:G9) -> 42
D12: TOTAL | E12: =SUM(E2:E9) -> 4891 | F12: =SUM(F2:F9) -> 4831 | G12: =SUM(G2:G9) -> 3256
D13: NUMBER OF DUPLICATES REMOVED | G13: =E10-G12 -> 1549
G20: =(E10-F10)+(E11-F11) -> 60
G21: =E12-G12 -> 1635

Sheet 3_screening
A1: study_id | B1: first_author | C1: authors | D1: year | E1: title | F1: source | G1: type | H1: doi | I1: link_url | J1: dbase | K1: select_on_title_abs | L1: text_retrievable | M1: select_on_full_text | N1: excluded_reason | O1: notes
A2: Sclifó Zucon_Pedreira_Vargas_etal_2022 | B2: Sclifó Zucon | C2: SclifÃ³ Zucon A.R.; Pedreira G.Q.; Vargas Motta A.C.; Gotz L.F.; Maeda S.; Martins Bassaco M.V.; Magri E.; Prior S.A.; de Paula Souza L.C.; de Oliveira Junior J.C. | D2: 2022 | E2: Piling Secondary Subtropical Forest Residue: Long-Term Impacts on Soil, Trees, and Weeds | F2: Forests | G2: article | H2: https://doi.org/10.3390/f13081183 | I2: https://www.scopus.com/inward/record.uri?eid=2-s2.0-85137560174&doi=10.3390%2ff13081183&partnerID=40&md5=cbbea97332b60567fab1888abf0e36ef | J2: Scopus | K2: keep | L2: yes | M2: drop | N2: population | O2: Use of UAV derived NDVI to evaluate vegetation regrowth as an indocator of soil recovery after piling residues, subtropical, was initially screened in but closer review of paper reveals this is an intensive tree plantation with added fertilizer treatments etc... so removed
A3: Conrad-Rooney_Barker_Pasquarella_etal_2021 | B3: Conrad-Rooney | C3: Conrad-Rooney E.; Barker Plotkin A.; Pasquarella V.J.; Elkinton J.; Chandler J.L.; Matthes J.H. | D3: 2021 | E3: Defoliation severity is positively related to soil solution nitrogen availability and negatively related to soil nitrogen concentrations following a multi-year invasive insect irruption | F3: AoB PLANTS | G3: article | H3: https://doi.org/10.1093/aobpla/plaa059 | I3: https://www.scopus.com/inward/record.uri?eid=2-s2.0-85099435960&doi=10.1093%2faobpla%2fplaa059&partnerID=40&md5=93c8bf37f28030b7dcfef8e743258eb6 | J3: Scopus | K3: keep | L3: yes | M3: keep | O3: Link between RS defoliation and in-situ soil nutrients, mainly N
A4: Sewell_Quideau_Dyck_etal_2020 | B4: Sewell | C4: Sewell P.D.; Quideau S.A.; Dyck M.; Macdonald E. | D4: 2020 | E4: Long-term effects of harvest on boreal forest soils in relation to a remote sensing-based soil moisture index | F4: Forest Ecology and Management | G4: article | H4: https://doi.org/10.1016/j.foreco.2020.117986 | I4: https://www.scopus.com/inward/record.uri?eid=2-s2.0-85079405075&doi=10.1016%2fj.foreco.2020.117986&partnerID=40&md5=a9c22c5e4316cb706282e584fb8f1094 | J4: Scopus | K4: keep | L4: yes | M4: keep | O4: Uses LiDAR to compute depth to water table and comapre with in-situ soil C and minerals in harvested and non-harvested forest stands
A5: Mohieddinne_Brasseur_Spicher_etal_2019 | B5: Mohieddinne | C5: Mohieddinne H.; Brasseur B.; Spicher F.; Gallet-Moron E.; Buridant J.; Kobaissi A.; Horen H. | D5: 2019 | E5: Physical recovery of forest soil after compaction by heavy machines, revealed by penetration resistance over multiple decades | F5: Forest Ecology and Management | G5: article | H5: https://doi.org/10.1016/j.foreco.2019.117472 | I5: https://www.scopus.com/inward/record.uri?eid=2-s2.0-85069650177&doi=10.1016%2fj.foreco.2019.117472&partnerID=40&md5=fc9e63bc82d557235b81804f4dbf61b8 | J5: Scopus | K5: keep | L5: yes | M5: keep | O5: LiDAR used solely to identify machine trails then perfrom in-situ measurement of soil compaction with penetrometer
A6: Lewis_Robichaud_Hudak_etal_2012 | B6: Lewis | C6: Sarah A. Lewis, Peter R. Robichaud, Andrew T. Hudak, Brian Austin, Robert J. Liebermann | D6: 2012 | E6: Utility of remotely sensed imagery for assessing the impact of salvage logging after forest fires | F6: Remote Sensing | G6: article | H6: https://doi.org/10.3390/rs4072112 | I6: https://research.fs.usda.gov/treesearch/41111 | J6: USFSTreesearch | K6: keep | L6: yes | M6: keep
A7: Morgan_Keane_Dillon_etal_2014 | B7: Morgan | C7: Penelope Morgan, Robert E. Keane, Gregory K. Dillon, Theresa B. Jain, Andrew T. Hudak, Eva C. Karau, Pamela G. Sikkink, Zachery A. Holden, Eva K. Strand | D7: 2014 | E7: Challenges of assessing fire and burn severity using field measures, remote sensing and modelling | F7: International Journal of Wildland Fire | G7: article | H7: https://doi.org/10.1071/WF13058 | I7: https://research.fs.usda.gov/treesearch/47843 | J7: USFSTreesearch | K7: keep | L7: yes | M7: keep
A8: Sikkink | B8: Sikkink | C8: Pamela G. Sikkink | D8: 2015 | E8: Comparison of six fire severity classification methods using Montana and Washington wildland fires | F8: USDA Forest Service Proceedings | G8: conference-paper | I8: https://research.fs.usda.gov/treesearch/49447 | J8: USFSTreesearch | K8: keep | L8: yes | M8: keep | O8: Directly relates RS burn severity indicators to CBI and soil burn index
A9: Lewis_Hudak_Robichaud_etal_2017 | B9: Lewis | C9: Sarah A. Lewis, Andrew T. Hudak, Peter R. Robichaud, Penelope Morgan, Kevin L. Satterberg, Eva K. Strand, Alistair M. S. Smith, Joseph A. Zamudio, Leigh B. Lentile | D9: 2017 | E9: Indicators of burn severity at extended temporal scales: a decade of ecosystem response in mixed-conifer forests of western Montana | F9: International Journal of Wildland Fire | G9: article | H9: https://doi.org/10.1071/WF17019 | I9: https://research.fs.usda.gov/treesearch/55517 | J9: USFSTreesearch | K9: keep | L9: yes | M9: keep | O9: RS burn indices correllated to field plots for spectral unmixing analysis, including soil endmembers
A10: Lewis_Robichaud_Elliot_etal_2004 | B10: Lewis | C10: Sarah A. Lewis, Peter R. Robichaud, William J. Elliot, Bruce E. Frazier, Joan Q. Wu | D10: 2004 | E10: Hyperspectral remote sensing of postfire soil properties | F10: American Society of Photogrammetry and Remote Sensing Conference Proceedings | G10: conference-paper | I10: https://research.fs.usda.gov/treesearch/23527 | J10: USFSTreesearch | K10: keep | L10: yes | M10: keep
A11: Hudak_Robichaud_Jain_etal_2004 | B11: Hudak | C11: Andrew Hudak, Pete Robichaud, Terrie Jain, Penelope Morgan, Carter Stone, Jess Clark | D11: 2004 | E11: The relationship of field burn severity measures to satellite-derived Burned Area Reflectance Classification (BARC) maps | F11: American Society of Photogrammetry and Remote Sensing Conference Proceedings | G11: conference-paper | I11: https://research.fs.usda.gov/treesearch/26195 | J11: USFSTreesearch | K11: keep | L11: yes | M11: keep | O11: Post-fire RS indices correlated to field measurement including soil indicators
A12: Hudak_Robichaud_Evans_etal_2004 | B12: Hudak | C12: Andrew T. Hudak, Peter R. Robichaud, Jeffery B. Evans, Jess Clark, Keith Lannom, Penelope Morgan, Carter Stone | D12: 2004 | E12: Field validation of Burned Area Reflectance Classification (BARC) products for post fire assessment | F12: American Society of Photogrammetry and Remote Sensing Conference Proceedings | G12: conference-paper | I12: https://research.fs.usda.gov/treesearch/23530 | J12: USFSTreesearch | K12: keep | L12: yes | M12: keep | O12: Post-fire RS indices correlated to field measurement including soil indicators
A13: Hudak_Morgan_Bobbitt_etal_2007 | B13: Hudak | C13: Andrew T. Hudak, Penelope Morgan, Michael J. Bobbitt, Allstair M. S. Smith, Sarah A. Lewis, Leigh B. Lentile, Peter R. Robichaud, Jess T. Clark, Randy A. McKinley | D13: 2007 | E13: The relationship of multispectral satellite imagery to immediate fire effects | F13: Fire Ecology | G13: article | H13: https://doi.org/10.4996/fireecology.0301064 | I13: https://research.fs.usda.gov/treesearch/29489 | J13: USFSTreesearch | K13: keep | L13: yes | M13: keep
A14: Verbyla_Lord_2008 | B14: Verbyla | C14: D. Verbyla, R. Lord | D14: 2008 | E14: Estimating post-fire organic soil depth in the Alaskan boreal forest using the Normalized Burn Ratio | F14: International Journal of Remote Sensing | G14: article | H14: https://doi.org/10.1080101431160701802497 | I14: https://research.fs.usda.gov/treesearch/35232 | J14: USFSTreesearch | K14: keep | L14: yes | M14: keep | O14: Post-fire NBR compared to in-situ organic soil depth
A15: Melander_Ritala_2018 | B15: Melander | C15: Lari Melander;Risto Ritala | D15: 2018 | E15: Time-of-flight imaging for assessing soil deformations and improving forestry vehicle tracking accuracy | F15: International Journal of Forest Engineering | G15: article | H15: https://doi.org/10.1080/14942119.2018.1421341 | I15: https://doi.org/10.1080/14942119.2018.1421341 | J15: OpenAlex | K15: keep | L15: yes | M15: keep | O15: Measure vehicle position and estimates rut depth in near real time using vehicle mounted sensors and software, in-situ rut depth measurements
A16: Lee_Elliott_Tiansawat_2023 | B16: Lee | C16: Lee K.; Elliott S.; Tiansawat P. | D16: 2023 | E16: Use of Drone RGB Imagery to Quantify Indicator Variables of Tropical-Forest-Ecosystem Degradation and Restoration | F16: Forests | G16: article | H16: https://doi.org/10.3390/f14030586 | I16: https://www.scopus.com/inward/record.uri?eid=2-s2.0-85151317509&doi=10.3390%2ff14030586&partnerID=40&md5=2c35118cf95a3946c8bb43f1c60d8a8f | J16: Scopus | K16: keep | L16: yes | M16: keep | O16: RS estimates of forest degradation, ground-truthing with ground plots including indicators of vegetation structure and bare soil/rock
A17: Robichaud_Lewis_Brown_etal_2020 | B17: Robichaud | C17: Robichaud, Peter R. ; Lewis, Sarah A. ; Brown, Robert E. ; Bone, Edwin D. ; Brooks, Erin S. | D17: 2020 | E17: Evaluating post-wildfire logging-slash cover treatment to reduce hillslope erosion after salvage logging using ground measurements and remote sensing | F17: Hydrological Processes | G17: analytic | H17: https://doi.org/10.1002/hyp.13882 | I17: https://research.ebsco.com/linkprocessor/plink?id=d3c53c39-0c96-3d2a-8bd7-33d879808112 | J17: EBSCOhost | K17: keep | L17: yes | M17: keep
A18: Giannetti_Chirici_Travaglini_etal_2017 | B18: Giannetti | C18: Giannetti, Francesca ; Chirici, Gherardo ; Travaglini, Davide ; Bottalico, Francesca ; Marchi, Enrico ; Cambi, Martina | D18: 2017 | E18: Assessment of soil disturbance caused by forest operations by means of portable laser scanner and soil physical parameters | F18: Soil Science Society of America Journal | G18: analytic | H18: https://doi.org/10.2136/sssaj2017.02.0051 | I18: https://research.ebsco.com/linkprocessor/plink?id=4378dfed-f1dc-38de-9046-ad9e964e6f49 | J18: EBSCOhost | K18: keep | L18: yes | M18: keep
A19: Bourgeau-Chavez_Kasischke_Riordan_etal_2007 | B19: Bourgeau-Chavez | C19: Laura Bourgeau-Chavez;Eric S. Kasischke;K. Riordan;S. Brunzell;M. C. Nolan;E. J. Hyer;J. Slawski;MÃ¡rta Medvecz;T.B. Walters;S. Ames | D19: 2007 | E19: Remote monitoring of spatial and temporal surface soil moisture in fire disturbed boreal forest ecosystems with ERS SAR imagery | F19: International Journal of Remote Sensing | G19: article | H19: https://doi.org/10.1080/01431160600976061 | I19: https://doi.org/10.1080/01431160600976061 | J19: OpenAlex | K19: keep | L19: yes | M19: keep | O19: RS radar soil moisture post-fire
A20: Salmivaara_Miettinen_Finér_etal_2018 | B20: Salmivaara | C20: Aura Salmivaara;Mikko Miettinen;Leena Finér;Samuli Launiainen;Heikki Korpunen;Sakari Tuominen;Jukka Heikkonen;Paavo Nevalainen;Matti SirÃ¨n;Jari Ala-IlomÃ¤ki;Jori Uusitalo | D20: 2018 | E20: Wheel rut measurements by forest machine-mounted LiDAR sensors – accuracy and potential for operational applications? | F20: International Journal of Forest Engineering | G20: article | H20: https://doi.org/10.1080/14942119.2018.1419677 | I20: https://doi.org/10.1080/14942119.2018.1419677 | J20: OpenAlex | K20: keep | L20: yes | M20: keep
A21: Beltrán-Marcos_Suárez-Seoane_Fernández-Guisuraga_etal_2021 | B21: Beltràn-Marcos | C21: David BeltrÃ¡n-Marcos;Susana SuÃ¡rez-Seoane;JosÃ© Manuel FernÃ¡ndez-Guisuraga;Victor FernÃ¡ndez-GarcÃ­a;Rayo Pinto;Paula GarcÃ­a-Llamas;Leonor Calvo | D21: 2021 | E21: Mapping Soil Burn Severity at Very High Spatial Resolution from Unmanned Aerial Vehicles | F21: Forests | G21: article | H21: https://doi.org/10.3390/f12020179 | I21: https://doi.org/10.3390/f12020179 | J21: OpenAlex | K21: keep | L21: yes | M21: keep
A22: French_Kasischke_Bourgeau-Chavez_etal_1996 | B22: French | C22: Nancy H. F. French;Eric S. Kasischke;Laura Bourgeau-Chavez;Peter Harrell | D22: 1996 | E22: Sensitivity of ERS-1 SAR to variations in soil water in fire-disturbed boreal forest ecosystems | F22: International Journal of Remote Sensing | G22: article | H22: https://doi.org/10.1080/01431169608949126 | I22: https://doi.org/10.1080/01431169608949126 | J22: OpenAlex | K22: keep | L22: yes | M22: keep | O22: RS radar to estimate soil moisture post-fire
A23: Bhatnagar_Puliti_Talbot_etal_2022 | B23: Bhatnagar | C23: Saheba Bhatnagar;Stefano Puliti;Bruce Talbot;Joachim B. Heppelmann;Johannes Breidenbach;Rasmus Astrup | D23: 2022 | E23: Mapping wheel-ruts from timber harvesting operations using deep learning techniques in drone imagery | F23: Forestry An International Journal of Forest Research | G23: article | H23: https://doi.org/10.1093/forestry/cpac023 | I23: https://doi.org/10.1093/forestry/cpac023 | J23: OpenAlex | K23: keep | L23: yes | M23: keep
A24: Heppelmann_Talbot_Antòn-Fernández_etal_2022 | B24: Heppelmann | C24: Joachim B. Heppelmann;Bruce Talbot;Clara AntÃ³n-FernÃ¡ndez;Rasmus Astrup | D24: 2022 | E24: Depth-to-water maps as predictors of rut severity in fully mechanized harvesting operations | F24: International Journal of Forest Engineering | G24: article | H24: https://doi.org/10.1080/14942119.2022.2044724 | I24: https://doi.org/10.1080/14942119.2022.2044724 | J24: OpenAlex | K24: keep | L24: yes | M24: keep
A25: Rengers_Tucker_Moody_etal_2016 | B25: Rengers | C25: Francis K. Rengers;Gregory E. Tucker;John A. Moody;Brian A. Ebel | D25: 2016 | E25: Illuminating wildfire erosion and deposition patterns with repeat terrestrial lidar | F25: Journal of Geophysical Research Earth Surface | G25: article | H25: https://doi.org/10.1002/2015jf003600 | I25: https://doi.org/10.1002/2015jf003600 | J25: OpenAlex | K25: keep | L25: yes | M25: keep
A26: McNeil_Beurs_Eshleman_etal_2007 | B26: McNeil | C26: Brenden E. McNeil;Kirsten M. de Beurs;Keith N. Eshleman;Jane R. Foster;Philip A. Townsend | D26: 2007 | E26: Maintenance of ecosystem nitrogen limitation by ephemeral forest disturbance: An assessment using MODIS, Hyperion, and Landsat ETM+ | F26: Geophysical Research Letters | G26: article | H26: https://doi.org/10.1029/2007gl031387 | I26: https://doi.org/10.1029/2007gl031387 | J26: OpenAlex | K26: keep | L26: yes | M26: keep | O26: RS indicators of N limitation/availability in soil
A27: Guilinger_Foufoula-Georgiou_Gray_etal_2023 | B27: Guilinger | C27: James Guilinger;Efi Foufoula-Georgiou;Andrew B. Gray;James T. Randerson;Padhraic Smyth;Nicolas C. Barth;Michael L. Goulden | D27: 2023 | E27: Predicting Postfire Sediment Yields of Small Steep Catchments Using Airborne Lidar Differencing | F27: Geophysical Research Letters | G27: article | H27: https://doi.org/10.1029/2023gl104626 | I27: https://doi.org/10.1029/2023gl104626 | J27: OpenAlex | K27: keep | L27: yes | M27: keep | O27: Uses LiDAR to map out pre- and post-fire differences and estimate soil erosion
A28: Mohieddinne_Brasseur_Gallet-Moron_etal_2022 | B28: Mohieddinne | C28: Hamza Mohieddinne;Boris Brasseur;Emilie Gallet-Moron;Jonathan Lenoir;Fabien Spicher;Ahmad Kobaissi;HÃ©lÃ¨ne Horen | D28: 2022 | E28: Assessment of soil compaction and rutting in managed forests through an airborne <scp>LiDAR</scp> technique | F28: Land Degradation and Development | G28: article | H28: https://doi.org/10.1002/ldr.4553 | I28: https://doi.org/10.1002/ldr.4553 | J28: OpenAlex | K28: keep | L28: yes | M28: keep
A29: Marquì­nez_Wozniak_Fernández_etal_2008 | B29: Marquì­nez | C29: J. Marquì­nez;Edyta Wozniak;Susana Fernández;Ricardo Martì­nez | D29: 2008 | E29: Analysis of the evolution of soil erosion classes using multitemporal Landsat imagery | F29: International Journal of Wildland Fire | G29: article | H29: https://doi.org/10.1071/wf06138 | I29: https://doi.org/10.1071/wf06138 | J29: OpenAlex | K29: keep | L29: yes | M29: keep
A30: Kubiak_Spiralski_Pompeu_etal_2024 | B30: Kubiak | C30: Katarzyna Kubiak;Marcin Spiralski;JoÃ£o Pompeu;Vincent Levavasseur;RafaÅ‚ Wawer | D30: 2024 | E30: Advances in Remote Sensing for Monitoring Soil Conditions in Forest Ecosystems: Techniques, Challenges, and Applications | F30: Transactions of the Institute of Aviation | G30: article | H30: https://doi.org/10.2478/tar-2024-0019 | I30: https://doi.org/10.2478/tar-2024-0019 | J30: OpenAlex | K30: keep | L30: yes | M30: keep
A31: Latterini_Venanzi_Tocci_etal_2020 | B31: Latterini | C31: Francesco Latterini;Rachele Venanzi;Damiano Tocci;Federico Moschetti;Rodolfo Picchio | D31: 2020 | E31: Comparing Accuracy of Three Remote Sensing Methods to Evaluate Soil Impact Related to Forest Operations | F31: NA | G31: article | H31: https://doi.org/10.3390/iecf2020-07954 | I31: https://doi.org/10.3390/iecf2020-07954 | J31: OpenAlex | K31: keep | L31: yes | M31: keep
A32: Dubé_Berch_2013 | B32: Dubé | C32: Stephane DubÃ©;Shannon M. Berch | D32: 2013 | E32: Monitoring soil disturbance on salvaged areas within the mountain pine beetle infestation using digital imagery | F32: Journal of Applied Remote Sensing | G32: article | H32: https://doi.org/10.1117/1.jrs.7.073541 | I32: https://doi.org/10.1117/1.jrs.7.073541 | J32: OpenAlex | K32: keep | L32: yes | M32: keep | O32: Review
A33: Baur_Friend_Pellegrini_2024 | B33: Baur | C33: Baur M.J.; Friend A.D.; Pellegrini A.F.A. | D33: 2024 | E33: Widespread and systematic effects of fire on plantâ€“soil water relations | F33: Nature Geoscience | G33: article | H33: https://doi.org/10.1038/s41561-024-01563-6 | I33: https://www.scopus.com/inward/record.uri?eid=2-s2.0-85208926269&doi=10.1038%2fs41561-024-01563-6&partnerID=40&md5=7da423dfb2749435e3deab079f6aafdd | J33: Scopus | K33: keep | L33: yes | M33: keep | O33: Using RS to investigate post-fire changes in soil and plant moisture.
A34: Llorens_Sobrino_Fernández_etal_2024 | B34: Llorens | C34: Llorens R.; Sobrino J.A.; FernÃ¡ndez C.; FernÃ¡ndez-Alonso J.M.; Vega J.A. | D34: 2024 | E34: Soil Burn Severity Assessment Using Sentinel-2 and Radiometric Measurements | F34: Fire | G34: article | H34: https://doi.org/10.3390/fire7120487 | I34: https://www.scopus.com/inward/record.uri?eid=2-s2.0-85213458686&doi=10.3390%2ffire7120487&partnerID=40&md5=9e96b2376d83f126c38f6d1144225aff | J34: Scopus | K34: keep | L34: yes | M34: keep | O34: correlation soil burns with S2
A35: Godziek_2024 | B35: Godziek | C35: Godziek J. | D35: 2024 | E35: Root plates of uprooted trees âˆ’ Automatic detection and biotransport estimation using LiDAR data and field mapping | F35: International Journal of Applied Earth Observation and Geoinformation | G35: article | H35: https://doi.org/10.1016/j.jag.2024.103992 | I35: https://www.scopus.com/inward/record.uri?eid=2-s2.0-85196815799&doi=10.1016%2fj.jag.2024.103992&partnerID=40&md5=88629a03095eeabeae591081345757d2 | J35: Scopus | K35: keep | L35: yes | M35: keep | O35: RS detection of root plates (likely from windthrow)
A36: Kadakci Koca_Küçükuysal_Gül_etal_2024 | B36: Kadakci | C36: Kadakci Koca T.; KÃ¼Ã§Ã¼kuysal C.; GÃ¼l M.; Esetlili T. | D36: 2024 | E36: A comprehensive approach to soil burn severity mapping for erosion susceptibility assessment | F36: Catena | G36: article | H36: https://doi.org/10.1016/j.catena.2024.108302 | I36: https://www.scopus.com/inward/record.uri?eid=2-s2.0-85201004093&doi=10.1016%2fj.catena.2024.108302&partnerID=40&md5=276b36f6a250d5e83dc24389fcbc81c9 | J36: Scopus | K36: keep | L36: yes | M36: keep
A37: Kim_Seo_Woo_etal_2025 | B37: Kim | C37: Kim I.; Seo J.; Woo H.; Choi B. | D37: 2025 | E37: Assessing Rutting and Soil Compaction Caused by Wood Extraction Using Traditional and Remote Sensing Methods | F37: Forests | G37: article | H37: https://doi.org/10.3390/f16010086 | I37: https://www.scopus.com/inward/record.uri?eid=2-s2.0-85216026180&doi=10.3390%2ff16010086&partnerID=40&md5=362110f118dc038a9b299cc7affe6419 | J37: Scopus | K37: keep | L37: yes | M37: keep
A38: Lewis_Robichaud_Archer_etal_2023 | B38: Lewis | C38: Lewis S.A.; Robichaud P.R.; Archer V.A.; Hudak A.T.; Eitel J.U.H.; Strand E.K. | D38: 2023 | E38: Informing Sustainable Forest Management: Remote Sensing Strategies for Assessing Soil Disturbance after Wildfire and Salvage Logging | F38: Forests | G38: article | H38: https://doi.org/10.3390/f14112218 | I38: https://www.scopus.com/inward/record.uri?eid=2-s2.0-85178337764&doi=10.3390%2ff14112218&partnerID=40&md5=bca91638a589bee8468b5679b483373a | J38: Scopus | K38: keep | L38: yes | M38: keep
A39: Venanzi_Latterini_Civitarese_etal_2023 | B39: Venanzi | C39: Venanzi R.; Latterini F.; Civitarese V.; Picchio R. | D39: 2023 | E39: Recent Applications of Smart Technologies for Monitoring the Sustainability of Forest Operations | F39: Forests | G39: review | H39: https://doi.org/10.3390/f14071503 | I39: https://www.scopus.com/inward/record.uri?eid=2-s2.0-85166181566&doi=10.3390%2ff14071503&partnerID=40&md5=8dc574b1c5c817ef837ae882709648a5 | J39: Scopus | K39: keep | L39: yes | M39: keep | O39: Review of RS in sustainable forestry, including methods for assessing rutthing and soil degradation
A40: Kim_Kim_Ha_etal_2023 | B40: Kim | C40: Kim J.; Kim I.; Ha E.; Choi B. | D40: 2023 | E40: UAV Photogrammetry for Soil Surface Deformation Detection in a Timber Harvesting Area, South Korea | F40: Forests | G40: article | H40: https://doi.org/10.3390/f14050980 | I40: https://www.scopus.com/inward/record.uri?eid=2-s2.0-85160741835&doi=10.3390%2ff14050980&partnerID=40&md5=e773b08423b8124135f0d3c63e38f6bf | J40: Scopus | K40: keep | L40: yes | M40: keep
...

Sheet 3.5_snowball
A1: CREATE A SIMILAR SHEET AS "3_screening" but for studies identifies through snowball sampling using 1) the Research Rabbit suggestions, and 2) a review of citations of articles screened IN
A2: study_id | B2: first_author | C2: authors | D2: year | E2: title | F2: source | G2: type | H2: doi | I2: link_url | J2: dbase | K2: select_on_title_abs | L2: text_retrievable | M2: select_on_full_text | N2: excluded_reason | O2: notes
A3: Lentile_Holden_Smith_etal_2006 | B3: Lentile | C3: Leigh B. Lentile;Zachary A. Holden;Alistair M. S. Smith;Michael J. Falkowski;Andrew T. Hudak;Penelope Morgan;Paul E. Gessler;Nathan C. Benson | D3: 2006 | E3: Remote sensing techniques to assess active fire characteristics and post-fire effects | F3: International Journal of Wildland Fire | G3: NA | H3: 10.1071/wf05097 | I3: NA | J3: ResearchRabbit | K3: drop
A4: Wing_Burnett_Sessions_etal_2014 | B4: Wing | C4: Michael G. Wing;Jonathan D. Burnett;John Sessions | D4: 2014 | E4: Remote Sensing and Unmanned Aerial System Technology for Monitoring and Quantifying Forest Fire Impacts | F4: International Journal of Remote Sensing Applications | G4: NA | H4: 10.14355/ijrsa.2014.0401.02 | I4: NA | J4: ResearchRabbit | K4: drop
A5: KoreÅˆ_Koren_SlanÄ_x008d_Ã­k_etal_2014 | B5: KoreÅˆ | C5: Milan KoreÅˆ;M. Koren;M. SlanÄ_x008d_Ã­k;Josef Suchomel;J. Dubina | D5: 2014 | E5: Use of terrestrial laser scanning to evaluate the spatial distribution of soil disturbance by skidding operations | F5: Iforest - Biogeosciences and Forestry | G5: Article | H5: 10.3832/ifor1165-007 | I5: NA | J5: ResearchRabbit | K5: keep | L5: yes | M5: keep
A6: Robichaud_Lewis_Laes_etal_2007 | B6: Robichaud | C6: Peter R. Robichaud;Sarah A. Lewis;Denise Laes;Andrew T. Hudak;Raymond F. Kokaly;Joseph A. Zamudio | D6: 2007 | E6: Postfire soil burn severity mapping with hyperspectral image unmixing | F6: Remote Sensing of Environment | G6: Article | H6: 10.1016/j.rse.2006.11.027 | I6: NA | J6: ResearchRabbit | K6: keep | L6: yes | M6: keep
A7: Parks_Dillon_Miller_etal_2014 | B7: Parks | C7: Sean A. Parks;Gregory K. Dillon;Carol Miller | D7: 2014 | E7: A New Metric for Quantifying Burn Severity: The Relativized Burn Ratio | F7: Remote Sensing | G7: NA | H7: 10.3390/rs6031827 | I7: NA | J7: ResearchRabbit | K7: keep | L7: yes | M7: drop | N7: outcome
A8: FernÃ¡ndez-GarcÃ­a_Santamarta_FernÃ¡ndezâ€“Manso_etal_2018 | B8: FernÃ¡ndez-GarcÃ­a | C8: VÃ­ctor FernÃ¡ndez-GarcÃ­a;MÃ³nica Santamarta;Alfonso FernÃ¡ndezâ€“Manso;Dar A. Roberts;Carmen Quintano;Elena Marcos;Leonor Calvo | D8: 2018 | E8: Burn severity metrics in fire-prone pine ecosystems along a climatic gradient using Landsat imagery | F8: Remote Sensing of Environment | G8: NA | H8: 10.1016/j.rse.2017.12.029 | I8: NA | J8: ResearchRabbit | K8: keep | L8: yes | M8: keep
A9: Doerr_Shakesby_Blake_etal_2006 | B9: Doerr | C9: Stefan H. Doerr;Richard A. Shakesby;William H. Blake;Chris J. Chafer;Geoff S. Humphreys;Peter Wallbrink | D9: 2006 | E9: Effects of differing wildfire severities on soil wettability and implications for hydrological response | F9: Journal of Hydrology | G9: NA | H9: 10.1016/j.jhydrol.2005.06.038 | I9: NA | J9: ResearchRabbit | K9: keep | L9: yes | M9: keep
A10: Vega_FontÃºrbel_Merino_etal_2013 | B10: Vega | C10: JosÃ© A. Vega;Teresa FontÃºrbel;AgustÄ±Ì_x0081_n Merino;Cristina FernÃ¡ndez;A. Ferreiro;Enrique JimÃ©nez | D10: 2013 | E10: Testing the ability of visual indicators of soil burn severity to reflect changes in soil chemical and microbial properties in pine forests and shrubland | F10: Plant and Soil | G10: NA | H10: 10.1007/s11104-012-1532-9 | I10: NA | J10: ResearchRabbit | K10: keep | L10: yes | M10: drop | N10: study design
A11: Campbell_White_Arp_etal_2013 | B11: Campbell | C11: David M.h. M.h. Campbell;Barry White;Paul A. Arp | D11: 2013 | E11: Modeling and mapping soil resistance to penetration and rutting using LiDAR-derived digital elevation data | F11: Journal of Soil and Water Conservation | G11: NA | H11: 10.2489/jswc.68.6.460 | I11: NA | J11: ResearchRabbit | K11: keep | L11: request | M11: keep | O11: Requested via NRCan Library 25-06-30
A12: Pohjankukka_RiihimÃ¤ki_Nevalainen_etal_2016 | B12: Pohjankukka | C12: Jonne Pohjankukka;Henri RiihimÃ¤ki;Paavo Nevalainen;Tapio Pahikkala;Jari Alaâ€_x0090_IlomÃ¤ki;Eija HyvÃ¶nen;J. Varjo;Jukka Heikkonen | D12: 2016 | E12: Predictability of boreal forest soil bearing capacity by machine learning | F12: Journal of Terramechanics | G12: NA | H12: 10.1016/j.jterra.2016.09.001 | I12: NA | J12: ResearchRabbit | K12: keep | L12: yes | M12: keep
A13: Veraverbeke_Dennison_Gitas_etal_2018 | B13: Veraverbeke | C13: Sander Veraverbeke;Philip E. Dennison;Ioannis Z. Gitas;Glynn Hulley;Ðž. Ð’. ÐšÐ°Ð»Ð°ÑˆÐ½Ð¸ÐºÐ¾Ð²Ð°;Olga V. Kalashnikova;Thomas Katagis;Le Kuai;Ran Meng;Dar A. Roberts;E. Natasha Stavros | D13: 2018 | E13: Hyperspectral remote sensing of fire: State-of-the-art and future perspectives | F13: Remote Sensing of Environment | G13: NA | H13: 10.1016/j.rse.2018.06.020 | I13: NA | J13: ResearchRabbit | K13: keep | L13: yes | M13: keep
A14: Quintano_Fernandez-Manso_Calvo_etal_2019 | B14: Roberts | C14: Dar A. Roberts;Carmen Quintano;Alfonso FernÃ¡ndezâ€“Manso;Leonor Calvo | D14: 2019 | E14: Vegetation and Soil Fire Damage Analysis Based on Species Distribution Modeling Trained with Multispectral Satellite Data | F14: Remote Sensing | G14: NA | H14: 10.3390/rs11151832 | I14: NA | J14: ResearchRabbit | K14: keep | L14: yes | M14: keep | O14: Had to manually correct author order
A15: Suvinen_Tokola_Saarilahti_etal_2009 | B15: Suvinen | C15: Antti Suvinen;Timo Tokola;Martti Saarilahti | D15: 2009 | E15: Terrain Trafficability Prediction with GIS Analysis | F15: Forest Science | G15: NA | H15: NA | I15: https://doi.org/10.1093/forestscience/55.5.433 | J15: ResearchRabbit | K15: keep | L15: request | M15: drop | N15: study design | O15: Requested via NRCan Library 25-06-30
A16: Nadalâ€_x0090_Romero_Revuelto_Errea_etal_2015 | B16: Nadalâ€_x0090_Romero | C16: Estela Nadalâ€_x0090_Romero;JesÃºs Revuelto;Paz Errea;J. I. LÃ³pezâ€_x0090_Moreno | D16: 2015 | E16: The application of terrestrial laser scanner and SfM photogrammetry in measuring erosion and deposition processes in two opposite slopes in a humid badlands area (central Spanish Pyrenees) | F16: NA | G16: NA | H16: 10.5194/soil-1-561-2015 | I16: NA | J16: ResearchRabbit | K16: keep | L16: yes | M16: drop | N16: population
A17: Smith_Vericat_etal_2015 | B17: Smith | C17: Mark E. Smith;DamiÃ Vericat | D17: 2015 | E17: From experimental plots to experimental landscapes: topography, erosion and deposition in subâ€_x0090_humid badlands from Structureâ€_x0090_fromâ€_x0090_Motion photogrammetry | F17: Earth Surface Processes and Landforms | G17: NA | H17: 10.1002/esp.3747 | I17: NA | J17: ResearchRabbit | K17: keep | L17: yes | M17: drop | N17: population
A18: Tanase_Kennedy_Aponte_etal_2015 | B18: Tanase | C18: Mihai A. Tanase;Robert E. Kennedy;Cristina Aponte | D18: 2015 | E18: Fire severity estimation from space: a comparison of active and passive sensors and their synergy for different forest types | F18: International Journal of Wildland Fire | G18: NA | H18: 10.1071/wf15059 | I18: NA | J18: ResearchRabbit | K18: keep | L18: yes | M18: drop | N18: outcome
A19: SÃ¡nchez_Bisquert_Rubio_etal_2015 | B19: SÃ¡nchez | C19: Juan Manuel SÃ¡nchez;Mar Bisquert;E. Rubio;Vicente Caselles | D19: 2015 | E19: Impact of Land Cover Change Induced by a Fire Event on the Surface Energy Fluxes Derived from Remote Sensing | F19: Remote Sensing | G19: NA | H19: 10.3390/rs71114899 | I19: NA | J19: ResearchRabbit | K19: keep | L19: yes | M19: drop | N19: outcome
A20: Johnstone_Kasischke_etal_2005 | B20: Johnstone | C20: Jill F. Johnstone;Eric S. Kasischke | D20: 2005 | E20: Stand-level effects of soil burn severity on postfire regeneration in a recently burned black spruce forest | F20: Canadian Journal of Forest Research | G20: NA | H20: 10.1139/x05-087 | I20: NA | J20: ResearchRabbit | K20: keep | L20: yes | M20: drop | N20: study design
A21: Case_Meng_Arp_etal_2005 | B21: Case | C21: Bradley S. Case;Fanâ€_x0090_Rui Meng;Paul A. Arp | D21: 2005 | E21: Digital elevation modelling of soil type and drainage within small forested catchments | F21: Canadian Journal of Soil Science | G21: NA | H21: 10.4141/s04-008 | I21: NA | J21: ResearchRabbit | K21: keep | L21: yes | M21: drop | N21: intervention
A22: Vlassova_PÃ©rezâ€_x0090_Cabello_Mimbrero_etal_2014 | B22: Vlassova | C22: Lidia Vlassova;Fernando PÃ©rezâ€_x0090_Cabello;Marcos Rodrigues Mimbrero;Raquel Montorio LloverÃ­a;Alberto GarcÃ­a-MartÃ­n | D22: 2014 | E22: Analysis of the Relationship between Land Surface Temperature and Wildfire Severity in a Series of Landsat Images | F22: Remote Sensing | G22: NA | H22: 10.3390/rs6076136 | I22: NA | J22: ResearchRabbit | K22: keep | L22: yes | M22: drop | N22: outcome
A23: MilenkoviÄ‡_Pfeifer_Glira_etal_2015 | B23: MilenkoviÄ‡ | C23: Milutin MilenkoviÄ‡;Norbert Pfeifer;Philipp Glira | D23: 2015 | E23: Applying Terrestrial Laser Scanning for Soil Surface Roughness Assessment | F23: Remote Sensing | G23: NA | H23: 10.3390/rs70202007 | I23: NA | J23: ResearchRabbit | K23: keep | L23: yes | M23: drop | N23: intervention
A24: Lewis_Wu_Wu_etal_2006 | B24: Lewis | C24: Sarah A. Lewis;Ji Wu;Joan Q. Wu;Peter R. Robichaud | D24: 2006 | E24: Assessing burn severity and comparing soil water repellency, Hayman Fire, Colorado | F24: Hydrological Processes | G24: NA | H24: 10.1002/hyp.5880 | I24: NA | J24: ResearchRabbit | K24: keep | L24: yes | M24: drop | N24: study design
A25: Jaboyedoff_Demers_Locat_etal_2009 | B25: Jaboyedoff | C25: Michel Jaboyedoff;Denis Demers;Jacques Locat;Thierry Oppikofer;Denis Robitaille;Dominique Turmel | D25: 2009 | E25: Use of terrestrial laser scanning for the characterization of retrogressive landslides in sensitive clay and rotational landslides in river banks | F25: Canadian Geotechnical Journal | G25: NA | H25: 10.1139/t09-073 | I25: NA | J25: ResearchRabbit | K25: keep | L25: yes | M25: drop | N25: population
A26: Chu_Guo_etal_2013 | B26: Chu | C26: Thuan Chu;Xulin Guo | D26: 2013 | E26: Remote Sensing Techniques in Monitoring Post-Fire Effects and Patterns of Forest Recovery in Boreal Forest Regions: A Review | F26: Remote Sensing | G26: NA | H26: 10.3390/rs6010470 | I26: NA | J26: ResearchRabbit | K26: keep | L26: yes | M26: drop | N26: study design
A27: FernÃ¡ndez_Vega_etal_2016 | B27: FernÃ¡ndez | C27: Cristina FernÃ¡ndez;JosÃ© A. Vega | D27: 2016 | E27: Modelling the effect of soil burn severity on soil erosion at hillslope scale in the first year following wildfire in NW Spain | F27: Earth Surface Processes and Landforms | G27: NA | H27: 10.1002/esp.3876 | I27: NA | J27: ResearchRabbit | K27: keep | L27: yes | M27: drop | N27: study design
A28: Fang_Yang_White_etal_2018 | B28: Fang | C28: Lei Fang;Jian Yang;Megan White;Zhihua Liu | D28: 2018 | E28: Predicting Potential Fire Severity Using Vegetation, Topography and Surface Moisture Availability in a Eurasian Boreal Forest Landscape | F28: Forests | G28: NA | H28: 10.3390/f9030130 | I28: NA | J28: ResearchRabbit | K28: keep | L28: yes | M28: drop | N28: study design
A29: Marcos_FernÃ¡ndez-GarcÃ­a_FernÃ¡ndezâ€“Manso_etal_2018 | B29: Marcos | C29: Elena Marcos;VÃ­ctor FernÃ¡ndez-GarcÃ­a;Alfonso FernÃ¡ndezâ€“Manso;Dar A. Roberts;Carmen Quintano;L. Valbuena;Reyes TÃ¡rrega;E. Luisâ€_x0090_Calabuig;Leonor Calvo | D29: 2018 | E29: Evaluation of Composite Burn Index and Land Surface Temperature for Assessing Soil Burn Severity in Mediterranean Fire-Prone Pine Ecosystems | F29: Forests | G29: NA | H29: 10.3390/f9080494 | I29: NA | J29: ResearchRabbit | K29: keep | L29: yes | M29: keep
A30: Foldager_Pedersen_Skov_etal_2019 | B30: Foldager | C30: Frederik F. Foldager;Johanna Pedersen;Esben Haubro Skov;Alevtina Evgrafova;Ole Green | D30: 2019 | E30: LiDAR-Based 3D Scans of Soil Surfaces and Furrows in Two Soil Types | F30: Sensors | G30: NA | H30: 10.3390/s19030661 | I30: NA | J30: ResearchRabbit | K30: keep | L30: yes | M30: drop | N30: population
A31: Jones_Arp_etal_2019 | B31: Jones | C31: Marie-France Jones;Paul A. Arp | D31: 2019 | E31: Analyzing and Projecting Soil Moisture and Cone Penetrability Variations in Forest Soils | F31: Open Journal of Forestry | G31: NA | H31: 10.4236/ojf.2019.92005 | I31: NA | J31: ResearchRabbit | K31: keep | L31: yes | M31: drop | N31: intervention
A32: Sobrino_Llorens_FernÃ¡ndez_etal_2019 | B32: Sobrino | C32: JosÃ© A. Sobrino;Rafael Llorens;Cristina FernÃ¡ndez;JosÃ© MarÃ­a FernÃ¡ndez-Alonso | D32: 2019 | E32: Relationship between Soil Burn Severity in Forest Fires Measured In Situ and through Spectral Indices of Remote Detection | F32: Forests | G32: NA | H32: 10.3390/f10050457 | I32: NA | J32: ResearchRabbit | K32: keep | L32: yes | M32: drop | N32: outcome
A33: Salmivaara_Launiainen_Perttunen_etal_2020 | B33: Salmivaara | C33: Aura Salmivaara;Samuli Launiainen;Jari Perttunen;Paavo Nevalainen;Jonne Pohjankukka;Jari Alaâ€_x0090_IlomÃ¤ki;Matti SirÃ©n;Jori Uusitalo;Tapio Pahikkala;Jukka Heikkonen;Leena FinÃ©r | D33: 2020 | E33: Towards dynamic forest trafficability prediction using open spatial data, hydrological modelling and sensor technology | F33: Forestry: An International Journal of Forest Research | G33: NA | H33: 10.1093/forestry/cpaa010 | I33: NA | J33: ResearchRabbit | K33: keep | L33: yes | M33: drop | N33: study design
A34: Han_Pageâ€_x0090_Dumroese_Johnson_etal_2009 | B34: Han | C34: Sang-Kyun Han;Deborah S. Pageâ€_x0090_Dumroese;Leonard R. Johnson | D34: 2009 | E34: Soil compaction associated with cut-to-length and whole-tree harvesting of a coniferous forest | F34: Canadian Journal of Forest Research | G34: NA | H34: 10.1139/x09-027 | I34: NA | J34: ResearchRabbit | K34: drop
A35: Jansson_etal_1998 | B35: Jansson | C35: Karl-Johan Jansson | D35: 1998 | E35: Soil changes after traffic with a tracked and a wheeled forest machine: a case study on a silt loam in Sweden | F35: Forestry | G35: NA | H35: 10.1093/forestry/71.1.57 | I35: NA | J35: ResearchRabbit | K35: drop
A36: Huang_Huang_Roy_etal_2016 | B36: Huang | C36: Hung-Chun Huang;Haiyan Huang;David P. Roy;Luigi Boschetti;Lin Yan;Sundeep Kumar;Sanath Sathyachandran Kumar;JosÃ© GÃ³mez-Dans;Jian Li | D36: 2016 | E36: Separability Analysis of Sentinel-2A Multi-Spectral Instrument (MSI) Data for Burned Area Discrimination | F36: Remote Sensing | G36: NA | H36: 10.3390/rs8100873 | I36: NA | J36: ResearchRabbit | K36: drop
A37: Fwa_Pasindu_Ong_etal_2012 | B37: Fwa | C37: T.f. Fwa;H.r. Pasindu;G. B. Ong;Ghim Ping Ong | D37: 2012 | E37: Critical Rut Depth for Pavement Maintenance Based on Vehicle Skidding and Hydroplaning Consideration | F37: Journal of Transportation Engineering-asce | G37: NA | H37: 10.1061/(asce)te.1943-5436.0000336 | I37: NA | J37: ResearchRabbit | K37: drop
A38: Botta_Becerra_Tourn_etal_2009 | B38: Botta | C38: Guido Fernando Botta;Alfredo TolÃ³n Becerra;F. Bellora Tourn | D38: 2009 | E38: Effect of the number of tractor passes on soil rut depth and compaction in two tillage regimes | F38: Soil & Tillage Research | G38: NA | H38: 10.1016/j.still.2008.12.002 | I38: NA | J38: ResearchRabbit | K38: drop
A39: Warneke_Gouw_Stohl_etal_2006 | B39: Warneke | C39: Carsten Warneke;J. A. De Gouw;Andreas Stohl;O. R. Cooper;P. D. Goldan;W. C. Kuster;J. S. Holloway;E. J. Williams;B. M. Lerner;S. A. Mckeen;M. Trainer;F. C. Fehsenfeld;Elliot L. Atlas;V. Stroud;A. Lueb;Shingo Kato | D39: 2006 | E39: Biomass burning and anthropogenic sources of CO over New England in the summer 2004 | F39: Journal of Geophysical Research | G39: NA | H39: 10.1029/2005jd006878 | I39: NA | J39: ResearchRabbit | K39: drop
A40: Grace_Skaggs_Cassel_etal_2006 | B40: Grace | C40: Johnny M. Grace;R. W. Skaggs;D. K. Cassel | D40: 2006 | E40: Soil Physical Changes Associated with Forest Harvesting Operations on an Organic Soil | F40: Soil Science Society of America Journal | G40: NA | H40: 10.2136/sssaj2005.0154 | I40: NA | J40: ResearchRabbit | K40: drop
...

Sheet 4_included_studies
A1: study_id | B1: first_author | C1: authors | D1: year | E1: title | F1: source | G1: pages | H1: issue | I1: volume | J1: type | K1: doi | L1: link_url | M1: dbase | N1: date_accessed
A2: Affek_Zachwatowicz_Sosnowska_etal_2017 | B2: Affek | C2: Affek, Andrzej Norbert; Zachwatowicz, Maria; Sosnowska, Agnieszka; Gerlée, Alina; Kiszka, Krzysztof | D2: 2017 | E2: Impacts of modern mechanised skidding on the natural and cultural heritage of the Polish Carpathian Mountains | F2: Forest Ecology and Management | G2: 391-403 | I2: 405 | J2: article | K2: https://doi.org/10.1016/j.foreco.2017.09.047 | L2: https://www.scopus.com/inward/record.uri?eid=2-s2.0-85030472101&doi=10.1016%2fj.foreco.2017.09.047&partnerID=40&md5=19ad50c4bc2f2318a4b70c90f20ec59b | M2: Scopus | N2: 45730.842
A3: Allen_Sorbel_2008 | B3: Allen | C3: Allen, Jennifer L.; Sorbel, Brian | D3: 2008 | E3: Assessing the differenced Normalized Burn Ratio's ability to map burn severity in the boreal forest and tundra ecosystems of Alaska's national parks | F3: International Journal of Wildland Fire | G3: 463 | H3: 4 | I3: 17 | J3: article | K3: https://doi.org/10.1071/wf08034 | L3: https://doi.org/10.1071/wf08034 | M3: OpenAlex | N3: 45730.765
A4: Baur_Friend_Pellegrini_2024 | B4: Baur | C4: Baur, Martin J.; Friend, Andrew D.; Pellegrini, Adam F. A. | D4: 2024 | E4: Widespread and systematic effects of fire on plant–soil water relations | F4: Nature Geoscience | G4: 1115-1120 | H4: 11 | I4: 17 | J4: article | K4: https://doi.org/10.1038/s41561-024-01563-6 | L4: https://www.scopus.com/inward/record.uri?eid=2-s2.0-85208926269&doi=10.1038%2fs41561-024-01563-6&partnerID=40&md5=7da423dfb2749435e3deab079f6aafdd | M4: Scopus | N4: 45733.882
A5: Beltrán-Marcos_Suárez-Seoane_Fernández-Guisuraga_etal_2021 | B5: Beltrán-Marcos | C5: Beltrán-Marcos, David; Suárez-Seoane, Susana; Fernández-Guisuraga, José Manuel; Fernández-García, Víctor; Marcos, Elena; Calvo, Leonor | D5: 2021 | E5: Relevance of UAV and Sentinel-2 data fusion for estimating topsoil organic carbon after forest fire | F5: Geoderma | G5: 116290 | I5: 430 | J5: article | K5: https://doi.org/10.3390/f12020179 | L5: https://doi.org/10.3390/f12020179 | M5: OpenAlex | N5: 45733.81
A6: Beltrán-Marcos_Suárez-Seoane_Fernández-Guisuraga_etal_2023 | B6: Beltrán-Marcos | C6: Beltrán-Marcos, David; Suárez-Seoane, Susana; Fernández-Guisuraga, José Manuel; Fernández-García, Víctor; Pinto, Rayo; García-Llamas, Paula; Calvo, Leonor | D6: 2023 | E6: Mapping soil burn severity at very high spatial resolution from unmanned aerial vehicles | F6: Forests | G6: 179 | H6: 2 | I6: 12 | J6: article | K6: https://doi.org/10.1016/j.geoderma.2022.116290 | L6: https://www.scopus.com/inward/record.uri?eid=2-s2.0-85143547946&doi=10.1016%2fj.geoderma.2022.116290&partnerID=40&md5=f1b894a19e66acf6192a77b0d72f1b43 | M6: Scopus | N6: 45735.659
A7: Bhatnagar_Puliti_Talbot_etal_2022 | B7: Bhatnagar | C7: Bhatnagar, Saheba; Puliti, Stefano; Talbot, Bruce; Heppelmann, Joachim Bernd; Breidenbach, Johannes; Astrup, Rasmus | D7: 2022 | E7: Mapping wheel-ruts from timber harvesting operations using deep learning techniques in drone imagery | F7: Forestry: An International Journal of Forest Research | G7: cpac023 | J7: article | K7: https://doi.org/10.1093/forestry/cpac023 | L7: https://doi.org/10.1093/forestry/cpac023 | M7: OpenAlex | N7: 45631.889
A8: Bourgeau-Chavez_Kasischke_Riordan_etal_2007 | B8: Bourgeau-Chavez | C8: Bourgeau‐Chavez, L. L.; Kasischke, E. S.; Riordan, K.; Brunzell, S.; Nolan, M.; Hyer, E.; Slawski, J.; Medvecz, M.; Walters, T.; Ames, S. | D8: 2007 | E8: Remote monitoring of spatial and temporal surface soil moisture in fire disturbed boreal forest ecosystems with ERS SAR imagery | F8: International Journal of Remote Sensing | G8: 2133-2162 | H8: 10 | I8: 28 | J8: article | K8: https://doi.org/10.1080/01431160600976061 | L8: https://doi.org/10.1080/01431160600976061 | M8: OpenAlex | N8: 45735.68
A9: Cambi_Giannetti_Bottalico_etal_2018 | B9: Cambi | C9: Cambi, M; Giannetti, F; Bottalico, F; Travaglini, D; Nordfjell, T; Chirici, G; Marchi, E | D9: 2018 | E9: Estimating machine impact on strip roads via close-range photogrammetry and soil parameters: A case study in central Italy | F9: iForest - Biogeosciences and Forestry | G9: 148-154 | H9: 1 | I9: 11 | J9: article | K9: https://doi.org/10.3832/ifor2590-010 | L9: https://www.scopus.com/inward/record.uri?eid=2-s2.0-85042373493&doi=10.3832%2fifor2590-010&partnerID=40&md5=036b72451714e07d37c137769d2b2a64 | M9: Scopus | N9: 45733.71
A10: Campbell_White_Arp_etal_2013 | B10: Campbell | C10: David M.h. M.h. Campbell;Barry White;Paul A. Arp | D10: 2013 | E10: Modeling and mapping soil resistance to penetration and rutting using LiDAR-derived digital elevation data | F10: Journal of Soil and Water Conservation | G10: 460-473 | I10: 68 | J10: article | K10: http://dx.doi.org/10.2489/jswc.68.6.460 | L10: https://www.researchgate.net/publication/271300317_Modeling_and_mapping_Soil_resistance_to_penetration_and_rutting_using_LiDAR-derived_digital_elevation_data | M10: ResearchRabbit | N10: 45838
A11: Chafer_2008 | B11: Chafer | C11: Chafer C.J. | D11: 2008 | E11: A comparison of fire severity measures: An Australian example and implications for predicting major areas of soil erosion | F11: Catena | G11: 235-245 | H11: 3 | I11: 74 | J11: article | K11: https://doi.org/10.1016/j.catena.2007.12.005 | L11: https://www.scopus.com/inward/record.uri?eid=2-s2.0-48649099656&doi=10.1016%2fj.catena.2007.12.005&partnerID=40&md5=ba7b1c9bde68c98770520520f43b7f45 | M11: Scopus | N11: 45838
A12: Chasmer_Hopkinson_Petrone_etal_2017 | B12: Chasmer | C12: Chasmer, L. E.; Hopkinson, C. D.; Petrone, R. M.; Sitar, M. | D12: 2017 | E12: Using multitemporal and multispectral airborne LiDAR to assess depth of peat loss and correspondence with a new Active Normalized Burn Ratio for wildfires | F12: Geophysical Research Letters | H12: 23 | I12: 44 | J12: article | K12: https://doi.org/10.1002/2017GL075488 | L12: https://www.scopus.com/inward/record.uri?eid=2-s2.0-85040089813&doi=10.1002%2f2017GL075488&partnerID=40&md5=fd7de5a5a4e602489ddd29f51ab8213e | M12: Scopus | N12: 45733.723
A13: Conrad-Rooney_Barker_Pasquarella_etal_2021 | B13: Conrad-Rooney | C13: Conrad-Rooney, Emma; Barker Plotkin, Audrey; Pasquarella, Valerie J; Elkinton, Joseph; Chandler, Jennifer L; Matthes, Jaclyn Hatala | D13: 2021 | E13: Defoliation severity is positively related to soil solution nitrogen availability and negatively related to soil nitrogen concentrations following a multi-year invasive insect irruption | F13: AoB PLANTS | G13: plaa059 | H13: 6 | I13: 12 | J13: article | K13: https://doi.org/10.1093/aobpla/plaa059 | L13: https://www.scopus.com/inward/record.uri?eid=2-s2.0-85099435960&doi=10.1093%2faobpla%2fplaa059&partnerID=40&md5=93c8bf37f28030b7dcfef8e743258eb6 | M13: Scopus | N13: 45737.654
A14: Dąbek_Żmuda_Szczepański_etal_2018 | B14: Dąbek | C14: Dąbek, Paweł B.; Żmuda, Romuald; Szczepański, Jakub; Ćmielewski, Bartłomiej | D14: 2018 | E14: Evaluation of water soil erosion processes in forest areas in the Western Sudetes using terrestrial laser scanning and GIS tools | F14: E3S Web of Conferences | G14: 26 | I14: 44 | J14: conference-paper | K14: https://doi.org/10.1051/e3sconf/20184400026 | L14: https://www.scopus.com/inward/record.uri?eid=2-s2.0-85051076068&doi=10.1051%2fe3sconf%2f20184400026&partnerID=40&md5=29beab9867d45df5817ff86be78d2a83 | M14: Scopus | N14: 45733.725
A15: Deligiannakis_Pallikarakis_Papanikolaou_etal_2021 | B15: Deligiannakis | C15: Deligiannakis, Georgios; Pallikarakis, Aggelos; Papanikolaou, Ioannis; Alexiou, Simoni; Reicherter, Klaus | D15: 2021 | E15: Detecting and monitoring early post-fire sliding phenomena using UAV–SfM photogrammetry and t-LiDAR-derived point clouds | F15: Fire | G15: 87 | H15: 4 | I15: 4 | J15: article | K15: https://doi.org/10.3390/fire4040087 | L15: https://www.scopus.com/inward/record.uri?eid=2-s2.0-85120166359&doi=10.3390%2ffire4040087&partnerID=40&md5=ebd04af5e35df3b196faa5b8c867d5b9 | M15: Scopus | N15: 45733.781
A16: Doerr_Shakesby_Blake_etal_2006 | B16: Doerr | C16: Stefan H. Doerr;Richard A. Shakesby;William H. Blake;Chris J. Chafer;Geoff S. Humphreys;Peter Wallbrink | D16: 2006 | E16: Effects of differing wildfire severities on soil wettability and implications for hydrological response | F16: Journal of Hydrology | G16: 295-311 | H16: 45661 | J16: article | K16: https://doi.org/10.1016/j.jhydrol.2005.06.038 | M16: ResearchRabbit | N16: 45840
A17: Dubé_Berch_2013 | B17: Dubé | C17: Dubé, Stéphane; Berch, Shannon | D17: 2013 | E17: Monitoring soil disturbance on salvaged areas within the mountain pine beetle infestation using digital imagery | F17: Journal of Applied Remote Sensing | G17: 73541 | H17: 1 | I17: 7 | J17: article | K17: https://doi.org/10.1117/1.jrs.7.073541 | L17: https://doi.org/10.1117/1.jrs.7.073541 | M17: OpenAlex | N17: 45733.888
A18: Ferenčík_Dudáková_Kardoš_etal_2022 | B18: Ferenčík | C18: Ferenčík, Michal; Dudáková, Zuzana; Kardoš, Miroslav; Sivák, Miroslav; Merganičová, Katarína; Merganič, Ján | D18: 2022 | E18: Measuring soil surface changes after traffic of various wheeled skidders with close-range photogrammetry | F18: Forests | G18: 976 | H18: 7 | I18: 13 | J18: article | K18: https://doi.org/10.3390/f13070976 | L18: https://www.scopus.com/inward/record.uri?eid=2-s2.0-85133207229&doi=10.3390%2ff13070976&partnerID=40&md5=c2ff3a85d6fa42a7df3976555097eb58 | M18: Scopus | N18: 45733.789
A19: Fernández_Fernández-Alonso_Vega_etal_2021 | B19: Fernández | C19: Fernández, Cristina; Fernández-Alonso, José M.; Vega, José A.; Fontúrbel, Teresa; Llorens, Rafael; Sobrino, José A. | D19: 2021 | E19: Exploring the use of spectral indices to assess alterations in soil properties in pine stands affected by crown fire in Spain | F19: Fire Ecology | G19: 2 | H19: 1 | I19: 17 | J19: article | K19: https://doi.org/10.1186/s42408-020-00089-7 | L19: https://www.scopus.com/inward/record.uri?eid=2-s2.0-85100187139&doi=10.1186%2fs42408-020-00089-7&partnerID=40&md5=8f895d1dec6d0cfa5bbb4326bccb76de | M19: Scopus | N19: 45733.785
A20: Fernandez-Garci­a_Santamarta_Fernandez-Manso_etal_2018 | B20: Fernandez-GarcÃia | C20: VÃ­ctor FernÃ¡ndez-GarcÃ­a;MÃ³nica Santamarta;Alfonso FernÃ¡ndezâ€“Manso;Dar A. Roberts;Carmen Quintano;Elena Marcos;Leonor Calvo | D20: 2018 | E20: Burn severity metrics in fire-prone pine ecosystems along a climatic gradient using Landsat imagery | F20: Remote Sensing of Environment | G20: 205-217 | I20: 206 | J20: article | K20: https://doi.org/10.1016/j.rse.2017.12.029 | L20: https://www.sciencedirect.com/science/article/pii/S0034425717306041 | M20: ResearchRabbit | N20: 45840
A21: Fernández-Guisuraga_Marcos_Suárez-Seoane_etal_2022 | B21: Fernández-Guisuraga | C21: Fernández-Guisuraga, José Manuel; Marcos, Elena; Suárez-Seoane, Susana; Calvo, Leonor | D21: 2022 | E21: ALOS-2 L-band SAR backscatter data improves the estimation and temporal transferability of wildfire effects on soil properties under different post-fire vegetation responses | F21: Science of The Total Environment | G21: 156852 | I21: 842 | J21: article | K21: https://doi.org/10.1016/j.scitotenv.2022.156852 | L21: https://www.scopus.com/inward/record.uri?eid=2-s2.0-85132935489&doi=10.1016%2fj.scitotenv.2022.156852&partnerID=40&md5=8277b1e9c58f8fccde560a535798fd36 | M21: Scopus | N21: 45733.797
A22: French_Kasischke_Bourgeau-Chavez_etal_1996 | B22: French | C22: French, N. H. F.; Kasischke, E. S.; Bourgeau-Chavez, L. L.; Harrell, P. A. | D22: 1996 | E22: Sensitivity of ERS-1 SAR to variations in soil water in fire-disturbed boreal forest ecosystems | F22: International Journal of Remote Sensing | G22: 3037-3053 | H22: 15 | I22: 17 | J22: article | K22: https://doi.org/10.1080/01431169608949126 | L22: https://doi.org/10.1080/01431169608949126 | M22: OpenAlex
